Workbook
Name Product_List: tblProductLookup[Product]
Name Slicer_Department: #N/A
Name Slicer_Quality_Status: #N/A
Name Slicer_Shift: #N/A

Sheet Dashboard
A1: MANUFACTURING PERFORMANCE DASHBOARD
A2: Production, Quality and Operational Performance Analysis
B4: Total Production Target | E4: Total Actual Production | H4: Overall Achievement % | K4: Total Defects | N4: Total Production Records
C6: =GETPIVOTDATA("Total Production_Target",Pivot_Analysis!$A$3) -> 236926 | F6: =GETPIVOTDATA("Total Actual_Production",Pivot_Analysis!$A$3) -> 221060 | I6: =Pivot_Analysis!D10 -> 0.93303394 | L6: =GETPIVOTDATA("Total Defects",Pivot_Analysis!$A$66) -> 10542 | O6: =GETPIVOTDATA("Production_ID",Pivot_Analysis!$A$49) -> 1195
C7: Units | F7: Units | H7: Achievement Rate | L7: Units | O7: Records
B9: 1. Department-wise Production Performance | I9: 2. Monthly Production Trend | M9: 5. Shift wise analysis
B21: 3. Quality Status Distribution | I21: 4. Product Performance
M23: MANAGEMENT INSIGHTS
M25: Best Achievement : | N25: =_xlfn.XLOOKUP(MAX(Pivot_Analysis!D4:D9),Pivot_Analysis!D4:D9,Pivot_Analysis!A4:A9) -> Machining | O25: =MAX(Pivot_Analysis!D4:D9) -> 0.93770612
M27: Highest Rejection Rate | N27: =_xlfn.XLOOKUP(MAX(Formula_Analysis!G35:G40),Formula_Analysis!G35:G40,Formula_Analysis!A35:A40)&" - "&TEXT(MAX(Formula_Analysis!G35:G40),"0.0%") -> Sheet Metal - 25.1%
M29: Highest Average Downtime | N29: =_xlfn.XLOOKUP(MAX(Formula_Analysis!B24:B29),Formula_Analysis!B24:B29,Formula_Analysis!A24:A29)&" - "&TEXT(MAX(Formula_Analysis!B24:B29),"0.00")&" Hours" -> Machining - 4.74 Hours
M31: Quality Performance | N31: =_xlfn.XLOOKUP(MAX(Formula_Analysis!H35:H40),Formula_Analysis!H35:H40,Formula_Analysis!A35:A40)&" - "&TEXT(MAX(Formula_Analysis!H35:H40),"0.0%") -> Machining - 62.8%

Sheet Raw_Data
A1: Production_ID | B1: Production_Date | C1: Product | D1: Department | E1: Machine | F1: Operator_ID | G1: Shift | H1: Production_Target | I1: Actual_Production | J1: Defects | K1: Downtime_Hours | L1: Material_Cost | M1: Labour_Hours | N1: Labour_Cost | O1: Order_Quantity | P1: Due_Date | Q1: Actual_Delivery_Date | R1: Quality_Status | S1: Customer
A2: PRD-00001 | B2: 46186 | C2: Composite Panel B | D2: Composite | E2: Autoclave-01 | F2: OP-008 | G2: Night | H2: 269 | I2: 225 | J2: 5 | K2: 6.6 | L2: 85638.51 | M2: 4.52 | N2: 108.48 | O2: 237 | P2: 46188 | Q2: 46187 | R2: Passed | S2: Precision Air
A3: PRD-00002 | B3: 46029 | C3: Machined Housing | D3: Machining | E3: CNC-04 | F3: OP-007 | G3: Evening | H3: 246 | I3: 251 | J3: 10 | K3: 4 | L3: 58016.75 | M3: 9.09 | N3: 181.8 | O3: 314 | P3: 46036 | Q3: 46036 | R3: Passed | S3: AeroTech UK
A4: PRD-00003 | B4: 46046 | C4: Repair Component | D4: Spares & Repairs | E4: Repair-01 | F4: OP-029 | G4: Evening | H4: 171 | I4: 185 | J4: 10 | K4: 7.3 | L4: 18621.51 | M4: 7.65 | N4: 183.6 | O4: 151 | P4: 46056 | Q4: 46056 | R4: Rejected | S4: Precision Air
A5: PRD-00004 | B5: 46072 | C5: Composite Panel B | D5: Composite | E5: Autoclave-01 | F5: OP-022 | G5: Evening | H5: 249 | I5: 203 | J5: 6 | K5: 0.7 | L5: 53070.63 | M5: 5.01 | N5: 110.22 | O5: 250 | P5: 46079 | Q5: 46080 | R5: Passed | S5: AeroTech UK
A6: PRD-00005 | B6: 46178 | C6: Sheet Metal Bracket | D6: Sheet Metal | E6: Bender-01 | F6: OP-013 | G6: Evening | H6: 266 | I6: 219 | J6: 10 | K6: 2.4 | L6: 31161.32 | M6: 5.1 | N6: 112.2 | O6: 240 | P6: 46183 | Q6: 46181 | R6: Passed | S6: AeroTech UK
A7: PRD-00006 | B7: 46077 | C7: Assembly Kit Y | D7: Assembly | E7: Assembly-01 | F7: OP-013 | G7: Evening | H7: 247 | I7: 230 | J7: 19 | K7: 5.8 | L7: 36223.11 | M7: 8.25 | N7: 214.5 | O7: 274 | P7: 46088 | Q7: 46090 | R7: Rejected | S7: NorthStar Aviation
A8: PRD-00007 | B8: 46058 | C8: Surface Treatment Part | D8: Surface Treatment | E8: Surface-01 | F8: OP-028 | G8: Day | H8: 273 | I8: 202 | J8: 3 | K8: 5.6 | L8: 31230.75 | M8: 3.94 | N8: 94.56 | O8: 352 | P8: 46068 | Q8: 46068 | R8: Rejected | S8: AeroTech UK
A9: PRD-00008 | B9: 46197 | C9: Assembly Kit X | D9: Assembly | E9: Assembly-03 | F9: OP-027 | G9: Night | H9: 167 | I9: 128 | J9: 5 | K9: 4.1 | L9: 28620.28 | M9: 3.11 | N9: 80.86 | O9: 172 | P9: 46207 | Q9: 46206 | R9: Passed | S9: Precision Air
A10: PRD-00009 | B10: 46178 | C10: Machined Housing | D10: Machining | E10: CNC-02 | F10: OP-002 | G10: Day | H10: 175 | I10: 183 | J10: 9 | K10: 7 | L10: 36636.42 | M10: 4.72 | N10: 84.96 | O10: 163 | P10: 46185 | Q10: 46185 | R10: Passed | S10: Precision Air
A11: PRD-00010 | B11: 46043 | C11: Composite Panel B | D11: Composite | E11: CNC-01 | F11: OP-030 | G11: Night | H11: 204 | I11: 218 | J11: 20 | K11: 4.8 | L11: 63700.32 | M11: 8.88 | N11: 177.6 | O11: 231 | P11: 46053 | Q11: 46055 | R11: Passed | S11: NorthStar Aviation
A12: PRD-00011 | B12: 46102 | C12: Repair Component | D12: Spares & Repairs | E12: Repair-02 | F12: OP-008 | G12: Day | H12: 192 | I12: 212 | J12: 9 | K12: 2.2 | L12: 14346.1 | M12: 6.63 | N12: 172.38 | O12: 208 | P12: 46104 | Q12: 46103 | R12: Passed | S12: AeroTech UK
A13: PRD-00012 | B13: 46107 | C13: Composite Panel B | D13: Composite | E13: CNC-01 | F13: OP-004 | G13: Night | H13: 140 | I13: 117 | J13: 5 | K13: 4.9 | L13: 45127.85 | M13: 3.72 | N13: 74.4 | O13: 221 | P13: 46115 | Q13: 46115 | R13: Passed | S13: Global Aero Systems
... A36: PRD-00035 | B36: 46112 | C36: Machined Housing | D36: Machining | E36: CNC-04 | F36: OP-019 | G36: Day | H36: 97 | I36: 102 | J36: 6 | K36: 6.8 | L36: 24910.85 | M36: 1.89 | N36: 37.8 | O36: 118 | P36: 46116 | Q36: 46120 | R36: Passed | S36: Global Aero Systems
A37: PRD-00036 | B37: 46202 | C37: Assembly Kit X | D37: Assembly | E37: Assembly-02 | F37: OP-023 | G37: Day | H37: 122 | I37: 119 | J37: 10 | K37: 6.5 | L37: 20800.9 | M37: 3.03 | N37: 78.78 | O37: 88 | P37: 46208 | Q37: 46210 | R37: Rework
A38: PRD-00037 | B38: 46174 | C38: Machined Housing | D38: Machining | E38: CNC-02 | F38: OP-017 | G38: Night | H38: 258 | I38: 271 | J38: 22 | K38: 5.4 | L38: 60429.22 | M38: 9.97 | N38: 219.34 | O38: 354 | P38: 46182 | Q38: 46183 | R38: Passed | S38: SkyWorks
A39: PRD-00038 | B39: 46026 | C39: Repair Component | D39: Spares & Repairs | E39: Repair-02 | F39: OP-014 | G39: Night | H39: 107 | I39: 96 | J39: 3 | K39: 8 | L39: 7901.83 | M39: 2.13 | N39: 55.38 | O39: 136 | P39: 46037 | Q39: 46041 | R39: Rework | S39: Precision Air
A40: PRD-00039 | B40: 46091 | C40: Assembly Kit Y | D40: Assembly | E40: Assembly-01 | F40: OP-016 | G40: Day | H40: 292 | I40: 327 | J40: 9 | K40: 4.1 | L40: 72639.54 | M40: 11.13 | N40: 244.86 | O40: 259 | P40: 46100 | Q40: 46101 | R40: Passed | S40: SkyWorks
A41: PRD-00040 | B41: 46089 | C41: Assembly Kit Y | D41: Assembly | E41: Assembly-02 | F41: OP-021 | G41: Night | H41: 305 | I41: 297 | J41: 25 | K41: 5 | L41: 54820.07 | M41: 7.07 | N41: 169.68 | O41: 390 | P41: 46099 | Q41: 46099 | R41: Rework | S41: Global Aero Systems
A42: PRD-00041 | B42: 46137 | C42: Composite Panel A | D42: Composite | E42: Autoclave-01 | F42: OP-009 | G42: Evening | H42: 155 | I42: 126 | J42: 8 | K42: 2.8 | L42: 34343.2 | M42: 3.87 | N42: 92.88 | O42: 255 | P42: 46144 | Q42: 46145 | R42: Rework | S42: SkyWorks
A43: PRD-00042 | B43: 46082 | C43: Composite Panel B | D43: Composite | E43: CNC-01 | F43: OP-027 | G43: Day | H43: 129 | I43: 110 | J43: 7 | K43: 8.6 | L43: 34919.08 | M43: 3.93 | N43: 86.46 | O43: 223 | P43: 46093 | Q43: 46093 | R43: Passed | S43: SkyWorks
A44: PRD-00043 | B44: 46081 | C44: Assembly Kit Y | D44: Assembly | E44: Assembly-01 | F44: OP-010 | G44: Evening | H44: 157 | I44: 113 | J44: 5 | K44: 2.5 | L44: 26840.19 | M44: 3.93 | N44: 78.6 | O44: 242 | P44: 46084 | Q44: 46082 | R44: Rejected | S44: Global Aero Systems
A45: PRD-00044 | B45: 46135 | C45: Assembly Kit Y | D45: Assembly | E45: Assembly-01 | F45: OP-008 | G45: Day | H45: 93 | I45: 77 | J45: 6 | K45: 1 | L45: 12963.18 | M45: 2.45 | N45: 44.1 | O45: 91 | P45: 46139 | Q45: 46139 | R45: Passed | S45: Precision Air
A46: PRD-00045 | B46: 46129 | C46: Machined Housing | D46: Machining | E46: CNC-04 | F46: OP-022 | G46: Day | H46: 177 | I46: 161 | J46: 7 | K46: 7.7 | L46: 41041.43 | M46: 5.3 | N46: 137.8 | O46: 162 | P46: 46134 | Q46: 46134 | R46: Passed | S46: NorthStar Aviation
A47: PRD-00046 | B47: 46084 | C47: Sheet Metal Bracket | D47: Sheet Metal | E47: Bender-01 | F47: OP-026 | G47: Night | H47: 99 | I47: 77 | J47: 3 | K47: 6.2 | L47: 7828.07 | M47: 1.92 | N47: 42.24 | O47: 175 | P47: 46087 | Q47: 46087 | R47: Passed | S47: Precision Air
A48: PRD-00047 | B48: 46192 | C48: Machined Housing | D48: Machining | E48: CNC-03 | F48: OP-023 | G48: Evening | H48: 109 | I48: 104 | J48: 6 | K48: 8.2 | L48: 23521.31 | M48: 2.29 | N48: 50.38 | O48: 142 | P48: 46201 | Q48: 46200 | R48: Rework | S48: Global Aero Systems
A49: PRD-00048 | B49: 46092 | C49: Surface Treatment Part | D49: Surface Treatment | E49: Surface-02 | F49: OP-002 | G49: Day | H49: 100 | I49: 97 | J49: 8 | K49: 6.6 | L49: 12551.48 | M49: 2.28 | N49: 59.28 | O49: 65 | P49: 46104 | Q49: 46104 | R49: Rejected | S49: Global Aero Systems
... A94: PRD-00093 | B94: 46186 | C94: Surface Treatment Part | D94: Surface Treatment | E94: Surface-01 | F94: OP-019 | G94: Evening | H94: 108 | I94: 116 | J94: 5 | K94: 4.8 | L94: 17709.61 | M94: 4.09 | N94: 89.98 | O94: 177 | P94: 46188 | Q94: 46189 | R94: Passed | S94: NorthStar Aviation
A95: PRD-00094 | B95: 46193 | C95: Composite Panel B | D95: Composite | E95: CNC-01 | F95: OP-009 | G95: Night | H95: 172 | J95: 6 | K95: 4.6 | L95: 49446.78 | M95: 3.5 | N95: 84 | O95: 143 | P95: 46205 | Q95: 46207 | R95: Passed | S95: AeroTech UK
A96: PRD-00095 | B96: 46114 | C96: Composite Panel B | D96: Composite | E96: Autoclave-02 | F96: OP-023 | G96: Evening | H96: 141 | I96: 145 | J96: 8 | K96: 6.9 | L96: 48650.32 | M96: 2.76 | N96: 71.76 | O96: 187 | P96: 46126 | Q96: 46126 | R96: Rework | S96: NorthStar Aviation
A97: PRD-00096 | B97: 46057 | C97: Composite Panel B | D97: Composite | E97: CNC-01 | F97: OP-002 | G97: Night | H97: 278 | I97: 312 | J97: 2 | K97: 1.8 | L97: 123159.7 | M97: 7.98 | N97: 175.56 | O97: 369 | P97: 46065 | Q97: 46069 | R97: Passed | S97: NorthStar Aviation
A98: PRD-00097 | B98: 46096 | C98: Assembly Kit Y | D98: Assembly | E98: Assembly-01 | F98: OP-012 | G98: Night | H98: 301 | I98: 301 | J98: 8 | K98: 7.2 | L98: 57266.04 | M98: 8.59 | N98: 206.16 | O98: 347 | P98: 46100 | Q98: 46104 | R98: Rework | S98: SkyWorks
A99: PRD-00098 | B99: 46044 | C99: Repair Component | D99: Spares & Repairs | E99: Repair-01 | F99: OP-023 | G99: Evening | H99: 190 | I99: 186 | J99: 14 | K99: 4.9 | L99: 14222.24 | M99: 6.3 | N99: 138.6 | O99: 264 | P99: 46055 | Q99: 46057 | R99: Passed | S99: SkyWorks
A100: PRD-00099 | B100: 46137 | C100: Composite Panel A | D100: Composite | E100: CNC-01 | F100: OP-005 | G100: Night | H100: 302 | I100: 335 | J100: 20 | K100: 3.9 | L100: 101152.3 | M100: 6.49 | N100: 155.76 | O100: 355 | P100: 46147 | Q100: 46147 | R100: Passed | S100: Global Aero Systems
A101: PRD-00100 | B101: 46031 | C101: Sheet Metal Bracket | D101: Sheet Metal | E101: Press-01 | F101: OP-005 | G101: Night | H101: 140 | I101: 147 | J101: 5 | K101: 3.4 | L101: 18184.5 | M101: 5.04 | N101: 110.88 | O101: 195 | P101: 46040 | Q101: 46039 | R101: Rejected | S101: SkyWorks
A102: PRD-00101 | B102: 46124 | C102: Assembly Kit Y | D102: Assembly | E102: Assembly-03 | F102: OP-010 | G102: Night | H102: 151 | I102: 124 | J102: 1 | K102: 6.6 | L102: 24044.4 | M102: 3.9 | N102: 85.8 | O102: 177 | P102: 46133 | Q102: 46133 | R102: Rejected | S102: Global Aero Systems
A103: PRD-00102 | B103: 46074 | C103: Composite Panel B | D103: Composite | E103: Autoclave-01 | F103: OP-028 | G103: Day | H103: 298 | I103: 224 | J103: 4 | K103: 6.4 | L103: 92638.49 | M103: 9.23 | N103: 203.06 | O103: 346 | P103: 46077 | Q103: 46077 | R103: Passed | S103: NorthStar Aviation
A104: PRD-00103 | B104: 46115 | C104: Machined Housing | D104: Machining | E104: CNC-02 | F104: OP-010 | G104: Evening | H104: 131 | I104: 138 | J104: 3 | K104: 4.4 | L104: 30546.88 | M104: 4.03 | N104: 104.78 | O104: 124 | P104: 46126 | Q104: 46125 | R104: Passed | S104: Global Aero Systems
A105: PRD-00104 | B105: 46157 | C105: Repair Component | D105: Spares & Repairs | E105: Repair-02 | F105: OP-030 | G105: Day | H105: 290 | I105: 280 | J105: 4 | K105: 2.9 | L105: 21629.09 | M105: 8.52 | N105: 170.4 | O105: 296 | P105: 46161 | Q105: 46163 | R105: Rejected | S105: AeroTech UK
A106: PRD-00105 | B106: 46155 | C106: Sheet Metal Bracket | D106: Sheet Metal | E106: Laser-01 | F106: OP-021 | G106: Evening | H106: 122 | I106: 96 | J106: 8 | K106: 2 | L106: 13160.6 | M106: 2.38 | N106: 42.84 | O106: 146 | P106: 46160 | Q106: 46160 | R106: Passed | S106: Precision Air
...

Sheet Clean_Data
A1: Production_ID | B1: Production_Date | C1: Product | D1: Department | E1: Machine | F1: Operator_ID | G1: Shift | H1: Production_Target | I1: Actual_Production | J1: Defects | K1: Downtime_Hours | L1: Material_Cost | M1: Labour_Hours | N1: Labour_Cost | O1: Order_Quantity | P1: Due_Date | Q1: Actual_Delivery_Date | R1: Quality_Status | S1: Customer
A2: PRD-00001 | B2: 46186 | C2: Composite Panel B | D2: Composite | E2: Autoclave-01 | F2: OP-008 | G2: Night | H2: 269 | I2: 225 | J2: 5 | K2: 6.6 | L2: 85638.51 | M2: 4.52 | N2: 108.48 | O2: 237 | P2: 46188 | Q2: 46187 | R2: Passed | S2: Precision Air
A3: PRD-00002 | B3: 46029 | C3: Machined Housing | D3: Machining | E3: CNC-04 | F3: OP-007 | G3: Evening | H3: 246 | I3: 251 | J3: 10 | K3: 4 | L3: 58016.75 | M3: 9.09 | N3: 181.8 | O3: 314 | P3: 46036 | Q3: 46036 | R3: Passed | S3: AeroTech UK
A4: PRD-00003 | B4: 46046 | C4: Repair Component | D4: Spares & Repairs | E4: Repair-01 | F4: OP-029 | G4: Evening | H4: 171 | I4: 185 | J4: 10 | K4: 7.3 | L4: 18621.51 | M4: 7.65 | N4: 183.6 | O4: 151 | P4: 46056 | Q4: 46056 | R4: Rejected | S4: Precision Air
A5: PRD-00004 | B5: 46072 | C5: Composite Panel B | D5: Composite | E5: Autoclave-01 | F5: OP-022 | G5: Evening | H5: 249 | I5: 203 | J5: 6 | K5: 0.7 | L5: 53070.63 | M5: 5.01 | N5: 110.22 | O5: 250 | P5: 46079 | Q5: 46080 | R5: Passed | S5: AeroTech UK
A6: PRD-00005 | B6: 46178 | C6: Sheet Metal Bracket | D6: Sheet Metal | E6: Bender-01 | F6: OP-013 | G6: Evening | H6: 266 | I6: 219 | J6: 10 | K6: 2.4 | L6: 31161.32 | M6: 5.1 | N6: 112.2 | O6: 240 | P6: 46183 | Q6: 46181 | R6: Passed | S6: AeroTech UK
A7: PRD-00006 | B7: 46077 | C7: Assembly Kit Y | D7: Assembly | E7: Assembly-01 | F7: OP-013 | G7: Evening | H7: 247 | I7: 230 | J7: 19 | K7: 5.8 | L7: 36223.11 | M7: 8.25 | N7: 214.5 | O7: 274 | P7: 46088 | Q7: 46090 | R7: Rejected | S7: NorthStar Aviation
A8: PRD-00007 | B8: 46058 | C8: Surface Treatment Part | D8: Surface Treatment | E8: Surface-01 | F8: OP-028 | G8: Day | H8: 273 | I8: 202 | J8: 3 | K8: 5.6 | L8: 31230.75 | M8: 3.94 | N8: 94.56 | O8: 352 | P8: 46068 | Q8: 46068 | R8: Rejected | S8: AeroTech UK
A9: PRD-00008 | B9: 46197 | C9: Assembly Kit X | D9: Assembly | E9: Assembly-03 | F9: OP-027 | G9: Night | H9: 167 | I9: 128 | J9: 5 | K9: 4.1 | L9: 28620.28 | M9: 3.11 | N9: 80.86 | O9: 172 | P9: 46207 | Q9: 46206 | R9: Passed | S9: Precision Air
A10: PRD-00009 | B10: 46178 | C10: Machined Housing | D10: Machining | E10: CNC-02 | F10: OP-002 | G10: Day | H10: 175 | I10: 183 | J10: 9 | K10: 7 | L10: 36636.42 | M10: 4.72 | N10: 84.96 | O10: 163 | P10: 46185 | Q10: 46185 | R10: Passed | S10: Precision Air
A11: PRD-00010 | B11: 46043 | C11: Composite Panel B | D11: Composite | E11: CNC-01 | F11: OP-030 | G11: Night | H11: 204 | I11: 218 | J11: 20 | K11: 4.8 | L11: 63700.32 | M11: 8.88 | N11: 177.6 | O11: 231 | P11: 46053 | Q11: 46055 | R11: Passed | S11: NorthStar Aviation
A12: PRD-00011 | B12: 46102 | C12: Repair Component | D12: Spares & Repairs | E12: Repair-02 | F12: OP-008 | G12: Day | H12: 192 | I12: 212 | J12: 9 | K12: 2.2 | L12: 14346.1 | M12: 6.63 | N12: 172.38 | O12: 208 | P12: 46104 | Q12: 46103 | R12: Passed | S12: AeroTech UK
A13: PRD-00012 | B13: 46107 | C13: Composite Panel B | D13: Composite | E13: CNC-01 | F13: OP-004 | G13: Night | H13: 140 | I13: 117 | J13: 5 | K13: 4.9 | L13: 45127.85 | M13: 3.72 | N13: 74.4 | O13: 221 | P13: 46115 | Q13: 46115 | R13: Passed | S13: Global Aero Systems
... A36: PRD-00035 | B36: 46112 | C36: Machined Housing | D36: Machining | E36: CNC-04 | F36: OP-019 | G36: Day | H36: 97 | I36: 102 | J36: 6 | K36: 6.8 | L36: 24910.85 | M36: 1.89 | N36: 37.8 | O36: 118 | P36: 46116 | Q36: 46120 | R36: Passed | S36: Global Aero Systems
A37: PRD-00036 | B37: 46202 | C37: Assembly Kit X | D37: Assembly | E37: Assembly-02 | F37: OP-023 | G37: Day | H37: 122 | I37: 119 | J37: 10 | K37: 6.5 | L37: 20800.9 | M37: 3.03 | N37: 78.78 | O37: 88 | P37: 46208 | Q37: 46210 | R37: Rework
A38: PRD-00037 | B38: 46174 | C38: Machined Housing | D38: Machining | E38: CNC-02 | F38: OP-017 | G38: Night | H38: 258 | I38: 271 | J38: 22 | K38: 5.4 | L38: 60429.22 | M38: 9.97 | N38: 219.34 | O38: 354 | P38: 46182 | Q38: 46183 | R38: Passed | S38: SkyWorks
A39: PRD-00038 | B39: 46026 | C39: Repair Component | D39: Spares & Repairs | E39: Repair-02 | F39: OP-014 | G39: Night | H39: 107 | I39: 96 | J39: 3 | K39: 8 | L39: 7901.83 | M39: 2.13 | N39: 55.38 | O39: 136 | P39: 46037 | Q39: 46041 | R39: Rework | S39: Precision Air
A40: PRD-00039 | B40: 46091 | C40: Assembly Kit Y | D40: Assembly | E40: Assembly-01 | F40: OP-016 | G40: Day | H40: 292 | I40: 327 | J40: 9 | K40: 4.1 | L40: 72639.54 | M40: 11.13 | N40: 244.86 | O40: 259 | P40: 46100 | Q40: 46101 | R40: Passed | S40: SkyWorks
A41: PRD-00040 | B41: 46089 | C41: Assembly Kit Y | D41: Assembly | E41: Assembly-02 | F41: OP-021 | G41: Night | H41: 305 | I41: 297 | J41: 25 | K41: 5 | L41: 54820.07 | M41: 7.07 | N41: 169.68 | O41: 390 | P41: 46099 | Q41: 46099 | R41: Rework | S41: Global Aero Systems
A42: PRD-00041 | B42: 46137 | C42: Composite Panel A | D42: Composite | E42: Autoclave-01 | F42: OP-009 | G42: Evening | H42: 155 | I42: 126 | J42: 8 | K42: 2.8 | L42: 34343.2 | M42: 3.87 | N42: 92.88 | O42: 255 | P42: 46144 | Q42: 46145 | R42: Rework | S42: SkyWorks
A43: PRD-00042 | B43: 46082 | C43: Composite Panel B | D43: Composite | E43: CNC-01 | F43: OP-027 | G43: Day | H43: 129 | I43: 110 | J43: 7 | K43: 8.6 | L43: 34919.08 | M43: 3.93 | N43: 86.46 | O43: 223 | P43: 46093 | Q43: 46093 | R43: Passed | S43: SkyWorks
A44: PRD-00043 | B44: 46081 | C44: Assembly Kit Y | D44: Assembly | E44: Assembly-01 | F44: OP-010 | G44: Evening | H44: 157 | I44: 113 | J44: 5 | K44: 2.5 | L44: 26840.19 | M44: 3.93 | N44: 78.6 | O44: 242 | P44: 46084 | Q44: 46082 | R44: Rejected | S44: Global Aero Systems
A45: PRD-00044 | B45: 46135 | C45: Assembly Kit Y | D45: Assembly | E45: Assembly-01 | F45: OP-008 | G45: Day | H45: 93 | I45: 77 | J45: 6 | K45: 1 | L45: 12963.18 | M45: 2.45 | N45: 44.1 | O45: 91 | P45: 46139 | Q45: 46139 | R45: Passed | S45: Precision Air
A46: PRD-00045 | B46: 46129 | C46: Machined Housing | D46: Machining | E46: CNC-04 | F46: OP-022 | G46: Day | H46: 177 | I46: 161 | J46: 7 | K46: 7.7 | L46: 41041.43 | M46: 5.3 | N46: 137.8 | O46: 162 | P46: 46134 | Q46: 46134 | R46: Passed | S46: NorthStar Aviation
A47: PRD-00046 | B47: 46084 | C47: Sheet Metal Bracket | D47: Sheet Metal | E47: Bender-01 | F47: OP-026 | G47: Night | H47: 99 | I47: 77 | J47: 3 | K47: 6.2 | L47: 7828.07 | M47: 1.92 | N47: 42.24 | O47: 175 | P47: 46087 | Q47: 46087 | R47: Passed | S47: Precision Air
A48: PRD-00047 | B48: 46192 | C48: Machined Housing | D48: Machining | E48: CNC-03 | F48: OP-023 | G48: Evening | H48: 109 | I48: 104 | J48: 6 | K48: 8.2 | L48: 23521.31 | M48: 2.29 | N48: 50.38 | O48: 142 | P48: 46201 | Q48: 46200 | R48: Rework | S48: Global Aero Systems
A49: PRD-00048 | B49: 46092 | C49: Surface Treatment Part | D49: Surface Treatment | E49: Surface-02 | F49: OP-002 | G49: Day | H49: 100 | I49: 97 | J49: 8 | K49: 6.6 | L49: 12551.48 | M49: 2.28 | N49: 59.28 | O49: 65 | P49: 46104 | Q49: 46104 | R49: Rejected | S49: Global Aero Systems
... A130: PRD-00130 | B130: 46140 | C130: Assembly Kit Y | D130: Assembly | E130: Assembly-01 | F130: OP-020 | G130: Day | H130: 150 | I130: 120 | J130: 10 | K130: 6.9 | L130: 20816.92 | M130: 3.93 | N130: 70.74 | O130: 171 | P130: 46145 | Q130: 46144 | R130: Passed | S130: Global Aero Systems
A131: PRD-00131 | B131: 46176 | C131: Composite Panel A | D131: Composite | E131: Autoclave-01 | F131: OP-020 | G131: Night | H131: 269 | I131: 198 | J131: 8 | K131: 4.9 | L131: 61902.75 | M131: 4.23 | N131: 93.06 | O131: 288 | P131: 46187 | Q131: 46188 | R131: Rejected
A132: PRD-00132 | B132: 46083 | C132: Assembly Kit X | D132: Assembly | E132: Assembly-01 | F132: OP-012 | G132: Night | H132: 249 | I132: 235 | J132: 9 | K132: 2.5 | L132: 42902.43 | M132: 8.38 | N132: 167.6 | O132: 318 | P132: 46093 | Q132: 46097 | R132: Passed | S132: Global Aero Systems
A133: PRD-00133 | B133: 46157 | C133: Assembly Kit Y | D133: Assembly | E133: Assembly-03 | F133: OP-018 | G133: Night | H133: 186 | I133: 166 | J133: 5 | K133: 1.7 | L133: 31323.47 | M133: 3.89 | N133: 77.8 | O133: 264 | P133: 46159 | Q133: 46161 | R133: Rework | S133: NorthStar Aviation
A134: PRD-00134 | B134: 46122 | C134: Machined Housing | D134: Machining | E134: CNC-03 | F134: OP-007 | G134: Night | H134: 132 | I134: 113 | J134: 1 | K134: 4 | L134: 24867.9 | M134: 4.28 | N134: 77.04 | O134: 160 | P134: 46130 | Q134: 46128 | R134: Passed | S134: Precision Air
A135: PRD-00135 | B135: 46078 | C135: Surface Treatment Part | D135: Surface Treatment | E135: Surface-01 | F135: OP-030 | G135: Day | H135: 302 | I135: 335 | J135: 10 | K135: 8.2 | L135: 39337.49 | M135: 11.99 | N135: 287.76 | O135: 324 | P135: 46089 | Q135: 46089 | R135: Rework | S135: Precision Air
A136: PRD-00136 | B136: 46105 | C136: Assembly Kit X | D136: Assembly | E136: Assembly-02 | F136: OP-014 | G136: Day | H136: 199 | I136: 188 | J136: 7 | K136: 2.4 | L136: 32956.93 | M136: 3.83 | N136: 91.92 | O136: 240 | P136: 46110 | Q136: 46111 | R136: Passed | S136: Precision Air
A137: PRD-00137 | B137: 46079 | C137: Sheet Metal Bracket | D137: Sheet Metal | E137: Press-01 | F137: OP-025 | G137: Evening | H137: 146 | I137: 139 | J137: 8 | K137: 6.5 | L137: 13894.88 | M137: 3.27 | N137: 85.02 | O137: 168 | P137: 46088 | Q137: 46089 | R137: Passed | S137: Global Aero Systems
A138: PRD-00138 | B138: 46140 | C138: Sheet Metal Bracket | D138: Sheet Metal | E138: Bender-01 | F138: OP-025 | G138: Day | H138: 283 | I138: 246 | J138: 4 | K138: 4.9 | L138: 28281.57 | M138: 10.27 | N138: 184.86 | O138: 377 | P138: 46142 | Q138: 46141 | R138: Passed | S138: Global Aero Systems
A139: PRD-00139 | B139: 46058 | C139: Machined Housing | D139: Machining | E139: CNC-02 | F139: OP-018 | G139: Evening | H139: 261 | I139: 204 | J139: 5 | K139: 4.1 | L139: 40702.49 | M139: 8.24 | N139: 197.76 | O139: 345 | P139: 46060 | Q139: 46058 | R139: Rejected | S139: AeroTech UK
A140: PRD-00140 | B140: 46027 | C140: Assembly Kit X | D140: Assembly | E140: Assembly-03 | F140: OP-020 | G140: Night | H140: 153 | I140: 111 | J140: 8 | K140: 6.1 | L140: 23880.61 | M140: 2.28 | N140: 41.04 | O140: 247 | P140: 46031 | Q140: 46031 | R140: Passed | S140: SkyWorks
A141: PRD-00141 | B141: 46113 | C141: Assembly Kit X | D141: Assembly | E141: Assembly-02 | F141: OP-013 | G141: Night | H141: 100 | I141: 88 | J141: 3 | K141: 5.1 | L141: 16752.16 | M141: 3.03 | N141: 54.54 | O141: 68 | P141: 46116 | Q141: 46118 | R141: Rework | S141: Global Aero Systems
A142: PRD-00142 | B142: 46037 | C142: Composite Panel A | D142: Composite | E142: CNC-01 | F142: OP-016 | G142: Evening | H142: 123 | I142: 92 | J142: 7 | K142: 5.8 | L142: 25991.02 | M142: 3.81 | N142: 99.06 | O142: 93 | P142: 46042 | Q142: 46042 | R142: Rejected | S142: AeroTech UK
...

Sheet Formula_Analysis
A1: Manufacturing Performance Formula Analysis
A3: 1. Product Lookup Analysis Xlookup :
A5: Product | B5: Department | C5: Standard_Unit_Cost | D5: Product_Manager
A6: Machined Housing | B6: =IFERROR(_xlfn.XLOOKUP(A6,Product_Lookup!$A$2:$A$10,Product_Lookup!$B$2:$B$10),"Product Not Found") -> Machining | C6: =IFERROR(_xlfn.XLOOKUP(A6,Product_Lookup!$A$2:$A$10,Product_Lookup!$C$2:$C$10),"Product Not Found") -> 360 | D6: =IFERROR(_xlfn.XLOOKUP(A6,Product_Lookup!$A$2:$A$10,Product_Lookup!$D$2:$D$10),"Product Not Found") -> Manager D
A9: 2. Department-wise Production Summary (SUMIFS)
A11: Department | B11: Total Production | C11: Total Target | D11: Achievement %
A12: {=_xlfn.UNIQUE(tblProduction[Department])} -> Composite | B12: =SUMIFS(Clean_Data!$I:$I,Clean_Data!$D:$D,A12) -> 56256 | C12: =SUMIFS(Clean_Data!$H:$H,Clean_Data!$D:$D,A12) -> 60199 | D12: =IFERROR(B12/C12,0) -> 0.93450057
A13: Machining | B13: =SUMIFS(Clean_Data!$I:$I,Clean_Data!$D:$D,A13) -> 23091 | C13: =SUMIFS(Clean_Data!$H:$H,Clean_Data!$D:$D,A13) -> 25078 | D13: =IFERROR(B13/C13,0) -> 0.92076721
A14: Spares & Repairs | B14: =SUMIFS(Clean_Data!$I:$I,Clean_Data!$D:$D,A14) -> 32773 | C14: =SUMIFS(Clean_Data!$H:$H,Clean_Data!$D:$D,A14) -> 34951 | D14: =IFERROR(B14/C14,0) -> 0.93768419
A15: Sheet Metal | B15: =SUMIFS(Clean_Data!$I:$I,Clean_Data!$D:$D,A15) -> 30708 | C15: =SUMIFS(Clean_Data!$H:$H,Clean_Data!$D:$D,A15) -> 32748 | D15: =IFERROR(B15/C15,0) -> 0.93770612
A16: Assembly | B16: =SUMIFS(Clean_Data!$I:$I,Clean_Data!$D:$D,A16) -> 51256 | C16: =SUMIFS(Clean_Data!$H:$H,Clean_Data!$D:$D,A16) -> 54726 | D16: =IFERROR(B16/C16,0) -> 0.93659321
A17: Surface Treatment | B17: =SUMIFS(Clean_Data!$I:$I,Clean_Data!$D:$D,A17) -> 26976 | C17: =SUMIFS(Clean_Data!$H:$H,Clean_Data!$D:$D,A17) -> 29224 | D17: =IFERROR(B17/C17,0) -> 0.92307692
B18: =SUM(B12:B17) -> 221060 | C18: =SUM(C12:C17) -> 236926 | D18: =IFERROR(B18/C18,0) -> 0.93303394
A21: 3. Department-wise Average Downtime Analysis (AVERAGEIFS)
A23: Department | B23: Average Downtime (Hours) | C23: Performance
A24: {=_xlfn.UNIQUE(tblProduction[Department])} -> Composite | B24: =AVERAGEIFS(Clean_Data!$K:$K,Clean_Data!$D:$D,A24) -> 4.3208609 | C24: =IF(B24<4.35,"Low Downtime",IF(B24<4.6,"Moderate Downtime","High Downtime")) -> Low Downtime
A25: Machining | B25: =AVERAGEIFS(Clean_Data!$K:$K,Clean_Data!$D:$D,A25) -> 4.7387597 | C25: =IF(B25<4.35,"Low Downtime",IF(B25<4.6,"Moderate Downtime","High Downtime")) -> High Downtime
A26: Spares & Repairs | B26: =AVERAGEIFS(Clean_Data!$K:$K,Clean_Data!$D:$D,A26) -> 4.3244318 | C26: =IF(B26<4.35,"Low Downtime",IF(B26<4.6,"Moderate Downtime","High Downtime")) -> Low Downtime
A27: Sheet Metal | B27: =AVERAGEIFS(Clean_Data!$K:$K,Clean_Data!$D:$D,A27) -> 4.2497006 | C27: =IF(B27<4.35,"Low Downtime",IF(B27<4.6,"Moderate Downtime","High Downtime")) -> Low Downtime
A28: Assembly | B28: =AVERAGEIFS(Clean_Data!$K:$K,Clean_Data!$D:$D,A28) -> 4.4945055 | C28: =IF(B28<4.35,"Low Downtime",IF(B28<4.6,"Moderate Downtime","High Downtime")) -> Moderate Downtime
A29: Surface Treatment | B29: =AVERAGEIFS(Clean_Data!$K:$K,Clean_Data!$D:$D,A29) -> 4.3790541 | C29: =IF(B29<4.35,"Low Downtime",IF(B29<4.6,"Moderate Downtime","High Downtime")) -> Moderate Downtime
A32: 4. Department-wise Quality Status Analysis (COUNTIFS)
A34: Department | B34: Passed | C34: Rework | D34: Rejected | E34: Not Recorded | F34: Total Records | G34: Rejection Rate % | H34: Passed Rate %
A35: {=_xlfn.UNIQUE(tblProduction[Department])} -> Composite | B35: =COUNTIFS(Clean_Data!$D:$D,$A35,Clean_Data!$R:$R,B$34) -> 184 | C35: =COUNTIFS(Clean_Data!$D:$D,$A35,Clean_Data!$R:$R,C$34) -> 60 | D35: =COUNTIFS(Clean_Data!$D:$D,$A35,Clean_Data!$R:$R,D$34) -> 58 | E35: =COUNTIFS(Clean_Data!$D:$D,$A35,Clean_Data!$R:$R,E$34) -> 0 | F35: =SUM(B35:E35) -> 302 | G35: =IFERROR(D35/F35,0) -> 0.19205298 | H35: =IFERROR(B35/F35,0) -> 0.60927152
A36: Machining | B36: =COUNTIFS(Clean_Data!$D:$D,$A36,Clean_Data!$R:$R,B$34) -> 81 | C36: =COUNTIFS(Clean_Data!$D:$D,$A36,Clean_Data!$R:$R,C$34) -> 25 | D36: =COUNTIFS(Clean_Data!$D:$D,$A36,Clean_Data!$R:$R,D$34) -> 23 | E36: =COUNTIFS(Clean_Data!$D:$D,$A36,Clean_Data!$R:$R,E$34) -> 0 | F36: =SUM(B36:E36) -> 129 | G36: =IFERROR(D36/F36,0) -> 0.17829457 | H36: =IFERROR(B36/F36,0) -> 0.62790698
A37: Spares & Repairs | B37: =COUNTIFS(Clean_Data!$D:$D,$A37,Clean_Data!$R:$R,B$34) -> 105 | C37: =COUNTIFS(Clean_Data!$D:$D,$A37,Clean_Data!$R:$R,C$34) -> 35 | D37: =COUNTIFS(Clean_Data!$D:$D,$A37,Clean_Data!$R:$R,D$34) -> 34 | E37: =COUNTIFS(Clean_Data!$D:$D,$A37,Clean_Data!$R:$R,E$34) -> 2 | F37: =SUM(B37:E37) -> 176 | G37: =IFERROR(D37/F37,0) -> 0.19318182 | H37: =IFERROR(B37/F37,0) -> 0.59659091
A38: Sheet Metal | B38: =COUNTIFS(Clean_Data!$D:$D,$A38,Clean_Data!$R:$R,B$34) -> 102 | C38: =COUNTIFS(Clean_Data!$D:$D,$A38,Clean_Data!$R:$R,C$34) -> 23 | D38: =COUNTIFS(Clean_Data!$D:$D,$A38,Clean_Data!$R:$R,D$34) -> 42 | E38: =COUNTIFS(Clean_Data!$D:$D,$A38,Clean_Data!$R:$R,E$34) -> 0 | F38: =SUM(B38:E38) -> 167 | G38: =IFERROR(D38/F38,0) -> 0.25149701 | H38: =IFERROR(B38/F38,0) -> 0.61077844
A39: Assembly | B39: =COUNTIFS(Clean_Data!$D:$D,$A39,Clean_Data!$R:$R,B$34) -> 166 | C39: =COUNTIFS(Clean_Data!$D:$D,$A39,Clean_Data!$R:$R,C$34) -> 51 | D39: =COUNTIFS(Clean_Data!$D:$D,$A39,Clean_Data!$R:$R,D$34) -> 54 | E39: =COUNTIFS(Clean_Data!$D:$D,$A39,Clean_Data!$R:$R,E$34) -> 2 | F39: =SUM(B39:E39) -> 273 | G39: =IFERROR(D39/F39,0) -> 0.1978022 | H39: =IFERROR(B39/F39,0) -> 0.60805861
A40: Surface Treatment | B40: =COUNTIFS(Clean_Data!$D:$D,$A40,Clean_Data!$R:$R,B$34) -> 79 | C40: =COUNTIFS(Clean_Data!$D:$D,$A40,Clean_Data!$R:$R,C$34) -> 37 | D40: =COUNTIFS(Clean_Data!$D:$D,$A40,Clean_Data!$R:$R,D$34) -> 32 | E40: =COUNTIFS(Clean_Data!$D:$D,$A40,Clean_Data!$R:$R,E$34) -> 0 | F40: =SUM(B40:E40) -> 148 | G40: =IFERROR(D40/F40,0) -> 0.21621622 | H40: =IFERROR(B40/F40,0) -> 0.53378378
A44: 5. Best and Worst Quality Performance Analysis (MAXIFS)
A46: Highest Rejection Rate | B46: =_xlfn.MAXIFS($G$35:$G$40,$G$35:$G$40,">0") -> 0.25149701
A47: Department with Highest Rejection | B47: =_xlfn.XLOOKUP(B46,$G$35:$G$40,$A$35:$A$40) -> Sheet Metal
A49: Lowest Rejection Rate | B49: =_xlfn.MINIFS($G$35:$G$40,$G$35:$G$40,">0") -> 0.17829457
A50: Department with Lowest Rejection | B50: =_xlfn.XLOOKUP(B49,$G$35:$G$40,$A$35:$A$40) -> Machining
A53: 6. Dynamic Production Record Filter (FILTER) | K53: 7: Dynamic Summary
A55: Select Department | B55: Composite | K55: Filtered Records | L55: =ROWS(_xlfn.ANCHORARRAY(A61)) -> 17
A56: Select Shift | B56: Day | K56: Total Production Target | L56: =SUM(INDEX(_xlfn.ANCHORARRAY(A61),,6)) -> 3389
A57: Select Quality Status | B57: Rejected | K57: Total Actual Production | L57: =SUM(INDEX(_xlfn.ANCHORARRAY(A61),,7)) -> 3212
K58: Total Defects | L58: =SUM(INDEX(_xlfn.ANCHORARRAY(A61),,8)) -> 171
K59: Average Achievement % | L59: =IFERROR(L57/L56,0) -> 0.9477722
...

Sheet Product_Lookup
A1: Product | B1: Department | C1: Standard_Unit_Cost | D1: Product_Manager
A2: Composite Panel A | B2: Composite | C2: 420 | D2: Manager A
A3: Composite Panel B | B3: Composite | C3: 510 | D3: Manager B
A4: Sheet Metal Bracket | B4: Sheet Metal | C4: 185 | D4: Manager C
A5: Machined Housing | B5: Machining | C5: 360 | D5: Manager D
A6: Assembly Kit X | B6: Assembly | C6: 275 | D6: Manager E
A7: Assembly Kit Y | B7: Assembly | C7: 315 | D7: Manager F
A8: Repair Component | B8: Spares & Repairs | C8: 145 | D8: Manager G
A9: Surface Treatment Part | B9: Surface Treatment | C9: 225 | D9: Manager H
A10: Sunglass | B10: Composite | C10: 120 | D10: Ali Akbar

Sheet Pivot_Analysis
A1: Pivot Table 1: Department-wise Production Analysis
G2: Chart 1: Department-wise Target vs Actual Production
A3: Row Labels | B3: Total Production_Target | C3: Total Actual_Production | D3: Achievement %
A4: Assembly | B4: 54726 | C4: 51256 | D4: =C5/B5 -> 0.93450057
A5: Composite | B5: 60199 | C5: 56256 | D5: =C6/B6 -> 0.92076721
A6: Machining | B6: 25078 | C6: 23091 | D6: =C7/B7 -> 0.93770612
A7: Sheet Metal | B7: 32748 | C7: 30708 | D7: =C8/B8 -> 0.93768419
A8: Spares & Repairs | B8: 34951 | C8: 32773 | D8: =C9/B9 -> 0.92307692
A9: Surface Treatment | B9: 29224 | C9: 26976 | D9: =C10/B10 -> 0.93303394
A10: Grand Total | B10: 236926 | C10: 221060 | D10: =GETPIVOTDATA("Total Actual_Production",$A$3)/GETPIVOTDATA("Total Production_Target",$A$3) -> 0.93303394
G20: Chart 2: Monthly Production Trend
A27: Pivot Table 2: Monthly Production Trend Analysis
A30: Row Labels | B30: Total Production Target | C30: Total Actual Production
A31: Jan | B31: 39822 | C31: 37533
A32: Feb | B32: 34674 | C32: 32042
A33: Mar | B33: 40453 | C33: 37742
A34: Apr | B34: 45024 | C34: 42130
A35: May | B35: 37848 | C35: 34987
A36: Jun | B36: 39105 | C36: 36626
A37: Grand Total | B37: 236926 | C37: 221060
A46: Pivot Table 3: Quality Status Analysis | G46: Chart 3: Quality Status Distribution
A49: Row Labels | B49: Total Production Record
A50: Not Recorded | B50: 4
A51: Passed | B51: 717
A52: Rejected | B52: 243
A53: Rework | B53: 231
A54: Grand Total | B54: 1195
A62: Pivot Table 4: Product-wise Performance Analysis | G62: Chart 4: Product-wise Actual Production
A66: Row Labels | B66: Total Production Target | C66: Total Actual Production | D66: Total Defects
A67: Machined Housing | B67: 25078 | C67: 23091 | D67: 1112
A68: Assembly Kit X | B68: 27207 | C68: 25202 | D68: 1077
A69: Composite Panel A | B69: 26739 | C69: 25288 | D69: 1268
A70: Assembly Kit Y | B70: 27519 | C70: 26054 | D70: 1312
A71: Surface Treatment Part | B71: 29224 | C71: 26976 | D71: 1218
A72: Sheet Metal Bracket | B72: 32748 | C72: 30708 | D72: 1456
A73: Composite Panel B | B73: 33460 | C73: 30968 | D73: 1538
A74: Repair Component | B74: 34951 | C74: 32773 | D74: 1561
A75: Grand Total | B75: 236926 | C75: 221060 | D75: 10542
A83: Pivot Table 5: Shift-wise Performance Analysis | G83: Chart 5: Shift-wise Actual Production vs Defects
B86: Total Production Target | C86: Total Actual Production | D86: Total Defects
...
